Workbook

Sheet Muraba Veil Sale Summary
A1: Muraba Veil Summary
A3: Muraba Veil Sale Summary
AK4: 3BR | AL4: 2BR | AM4: 2BR Delux | AN4: 2BR Ultra | AO4: 1BR | AP4: 1BR
A5: Typology | B5: Number of Units | C5: Price/Sq.ft | D5: Area (sqft) | E5: Area (sqm) | F5: Internal (sqft/unit) | G5: Terrace (sqft/unit) | H5: Total Internal (sqft) | I5: Total Terrace (sqft) | J5: Total Sellable | K5: Counted Terraces | L5: Total Sellable Counted | M5: Price (per unit) | N5: Total Sales | P5: Parking | Q5: Total Parking | AA5: 10.615884 | AB5: Sqr mtr to
A6: 2 Bedroom | B6: 54 | C6: =AVERAGEIF(Table2[[#Data],[#Totals],[Type]],'Muraba Veil Sale Summary'!A6,Table2[[#Data],[#Totals],[Price]])/AVERAGEIF(Table2[[#Data],[#Totals],[Type]],'Muraba Veil Sale Summary'!A6,Table2[[#Data],[#Totals],[Total Area (Sq.ft)]]) -> 5918.0471 | D6: =F6+G6 -> 3838.0875 | E6: =D6/10.7639104 -> 356.57 | F6: 2218.7649 | G6: 1619.3227 | H6: =F6*B6 -> 119813.3 | I6: =G6*B6 -> 87443.425 | J6: =H6+I6 -> 207256.73 | K6: =I6*$K$4 -> 0 | L6: =K6+H6 -> 119813.3 | M6: =C6*D6 -> 22713983 | N6: =M6*B6 -> 1.2265551e+09 | P6: 2 | Q6: =P6*'Muraba Veil Sale Summary'!$B6 -> 108 | S6: =Q6-R6 -> 108 | U6: ='Muraba Veil Sale Summary'!$M6/'Muraba Veil Sale Summary'!$D6 -> 5918.0471 | Y6: 4023.69 | AA6: =Y6/$AA$5 -> 379.02543
A7: 2 Bedroom - NEW | B7: =104-54 -> 50 | C7: =C6 -> 5918.0471 | D7: =F7+G7 -> 3838.0875 | E7: =D7/10.7639104 -> 356.57 | F7: 2218.7649 | G7: 1619.3227 | H7: =F7*B7 -> 110938.24 | I7: =G7*B7 -> 80966.134 | J7: =H7+I7 -> 191904.38 | K7: =I7*$K$4 -> 0 | L7: =K7+H7 -> 110938.24 | M7: =C7*D7 -> 22713983 | N7: =M7*B7 -> 1.1356991e+09
A8: 3 Bedroom | B8: =COUNTIF(Table2[Type],'Muraba Veil Sale Summary'!A8) -> 52 | C8: =AVERAGEIF(Table2[[#All],[Type]],'Muraba Veil Sale Summary'!A8,Table2[[#All],[Price]])/AVERAGEIF(Table2[[#All],[Type]],'Muraba Veil Sale Summary'!A8,Table2[[#All],[Total Area (Sq.ft)]]) -> 5299.8591 | D8: =F8+G8 -> 4939.4508 | E8: =D8/10.7639104 -> 458.89 | F8: 2880.5301 | G8: 2058.9208 | H8: =F8*B8 -> 149787.56 | I8: =G8*B8 -> 107063.88 | J8: =H8+I8 -> 256851.44 | K8: =I8*$K$4 -> 0 | L8: =K8+H8 -> 149787.56 | M8: =C8*D8 -> 26178394 | N8: =M8*B8 -> 1.3612765e+09 | P8: 2 | Q8: =P8*'Muraba Veil Sale Summary'!$B8 -> 104 | S8: =Q8-R8 -> 104 | U8: ='Muraba Veil Sale Summary'!$M8/'Muraba Veil Sale Summary'!$D8 -> 5299.8591 | Y8: 5124.52 | AA8: =Y8/$AA$5 -> 482.72192
A9: 3 Bedroom Pool | B9: =COUNTIF(Table2[Type],'Muraba Veil Sale Summary'!A9) -> 7 | C9: =AVERAGEIF(Table2[[#All],[Type]],'Muraba Veil Sale Summary'!A9,Table2[[#All],[Price]])/AVERAGEIF(Table2[[#All],[Type]],'Muraba Veil Sale Summary'!A9,Table2[[#All],[Total Area (Sq.ft)]]) -> 6416.9792 | D9: =F9+G9 -> 4939.7738 | E9: =D9/10.7639104 -> 458.92 | F9: 2880.5301 | G9: 2059.2437 | H9: =F9*B9 -> 20163.71 | I9: =G9*B9 -> 14414.706 | J9: =H9+I9 -> 34578.416 | K9: =I9*$K$4 -> 0 | L9: =K9+H9 -> 20163.71 | M9: =C9*D9 -> 31698425 | N9: =M9*B9 -> 2.2188898e+08 | P9: 2 | Q9: =P9*'Muraba Veil Sale Summary'!$B9 -> 14 | S9: =Q9-R9 -> 14 | U9: ='Muraba Veil Sale Summary'!$M9/'Muraba Veil Sale Summary'!$D9 -> 6416.9792 | Y9: 5124.52 | AA9: =Y9/$AA$5 -> 482.72192
A10: 4 Bedroom Pool | B10: =COUNTIF(Table2[Type],'Muraba Veil Sale Summary'!A10) -> 7 | C10: =AVERAGEIF(Table2[[#All],[Type]],'Muraba Veil Sale Summary'!A10,Table2[[#All],[Price]])/AVERAGEIF(Table2[[#All],[Type]],'Muraba Veil Sale Summary'!A10,Table2[[#All],[Total Area (Sq.ft)]]) -> 5002.2117 | D10: =F10+G10 -> 9902.367 | E10: =D10/10.7639104 -> 919.96 | F10: 4643.5509 | G10: 5258.8161 | H10: =F10*B10 -> 32504.857 | I10: =G10*B10 -> 36811.712 | J10: =H10+I10 -> 69316.569 | K10: =I10*$K$4 -> 0 | L10: =K10+H10 -> 32504.857 | M10: =C10*D10 -> 49533736 | N10: =M10*B10 -> 3.4673615e+08 | P10: 3 | Q10: =P10*'Muraba Veil Sale Summary'!$B10 -> 21 | R10: =SUM('[1]Muraba Unit Wise Details '!L101:L117) -> 5.7724938e+08 | S10: =Q10-R10 -> -5.7724936e+08 | U10: ='Muraba Veil Sale Summary'!$M10/'Muraba Veil Sale Summary'!$D10 -> 5002.2117 | Y10: 10105.89 | AA10: =Y10/$AA$5 -> 951.95933
A11: 3 Bedroom Duplex | B11: =COUNTIF(Table2[Type],'Muraba Veil Sale Summary'!A11) -> 1 | C11: =AVERAGEIF(Table2[[#All],[Type]],'Muraba Veil Sale Summary'!A11,Table2[[#All],[Price]])/AVERAGEIF(Table2[[#All],[Type]],'Muraba Veil Sale Summary'!A11,Table2[[#All],[Total Area (Sq.ft)]]) -> 9862.1634 | D11: =F11+G11 -> 8067.7661 | E11: =D11/10.7639104 -> 749.52 | F11: 4733.5372 | G11: 3334.2289 | H11: =F11*B11 -> 4733.5372 | I11: =G11*B11 -> 3334.2289 | J11: =H11+I11 -> 8067.7661 | K11: =I11*$K$4 -> 0 | L11: =K11+H11 -> 4733.5372 | M11: =C11*D11 -> 79565628 | N11: =M11*B11 -> 79565628 | P11: 3 | Q11: =P11*'Muraba Veil Sale Summary'!$B11 -> 3 | S11: =Q11-R11 -> 3 | U11: ='Muraba Veil Sale Summary'!$M11/'Muraba Veil Sale Summary'!$D11 -> 9862.1634 | Y11: 15121.69 | AA11: =Y11/$AA$5 -> 1424.44
A12: 4 Bedroom Simplex | B12: =COUNTIF(Table2[Type],'Muraba Veil Sale Summary'!A12) -> 1 | C12: =AVERAGEIF(Table2[[#All],[Type]],'Muraba Veil Sale Summary'!A12,Table2[[#All],[Price]])/AVERAGEIF(Table2[[#All],[Type]],'Muraba Veil Sale Summary'!A12,Table2[[#All],[Total Area (Sq.ft)]]) -> 10798.796 | D12: =F12+G12 -> 15332.545 | E12: =D12/10.7639104 -> 1424.44 | F12: 7474.8899 | G12: 7857.6546 | H12: =F12*B12 -> 7474.8899 | I12: =G12*B12 -> 7857.6546 | J12: =H12+I12 -> 15332.545 | K12: =I12*$K$4 -> 0 | L12: =K12+H12 -> 7474.8899 | M12: =C12*D12 -> 1.6557303e+08 | N12: =M12*B12 -> 1.6557303e+08 | P12: 4 | Q12: =P12*'Muraba Veil Sale Summary'!$B12 -> 4 | S12: =Q12-R12 -> 4 | U12: ='Muraba Veil Sale Summary'!$M12/'Muraba Veil Sale Summary'!$D12 -> 10798.796 | Y12: 15006.53 | AA12: =Y12/$AA$5 -> 1413.5921
A13: 4 Bedroom Duplex | B13: =COUNTIF(Table2[Type],'Muraba Veil Sale Summary'!A13) -> 1 | C13: =AVERAGEIF(Table2[[#All],[Type]],'Muraba Veil Sale Summary'!A13,Table2[[#All],[Price]])/AVERAGEIF(Table2[[#All],[Type]],'Muraba Veil Sale Summary'!A13,Table2[[#All],[Total Area (Sq.ft)]]) -> 10011.227 | D13: =F13+G13 -> 14745.696 | E13: =D13/10.7639104 -> 1369.92 | F13: 7485.6538 | G13: 7260.0423 | H13: =F13*B13 -> 7485.6538 | I13: =G13*B13 -> 7260.0423 | J13: =H13+I13 -> 14745.696 | K13: =I13*$K$4 -> 0 | L13: =K13+H13 -> 7485.6538 | M13: =C13*D13 -> 1.4762251e+08 | N13: =M13*B13 -> 1.4762251e+08 | P13: 4 | Q13: =P13*'Muraba Veil Sale Summary'!$B13 -> 4 | S13: =Q13-R13 -> 4 | U13: ='Muraba Veil Sale Summary'!$M13/'Muraba Veil Sale Summary'!$D13 -> 10011.227 | Y13: 25269.78 | AA13: =Y13/$AA$5 -> 2380.3745
A14: 5 Bedroom Duplex | B14: =COUNTIF(Table2[Type],'Muraba Veil Sale Summary'!A14) -> 1 | C14: =AVERAGEIF(Table2[[#All],[Type]],'Muraba Veil Sale Summary'!A14,Table2[[#All],[Price]])/AVERAGEIF(Table2[[#All],[Type]],'Muraba Veil Sale Summary'!A14,Table2[[#All],[Total Area (Sq.ft)]]) -> 16194.636 | D14: =F14+G14 -> 26666.73 | E14: =D14/10.7639104 -> 2477.4203 | F14: 11648.17 | G14: 15018.56 | H14: =F14*B14 -> 11648.17 | I14: =G14*B14 -> 15018.56 | J14: =H14+I14 -> 26666.73 | K14: =I14*$K$4 -> 0 | L14: =K14+H14 -> 11648.17 | M14: =C14*D14 -> 4.3185799e+08 | N14: =M14*B14 -> 4.3185799e+08 | P14: 6 | Q14: =P14*'Muraba Veil Sale Summary'!$B14 -> 6
A15: Total | B15: =SUM(B6:B14) -> 174 | H15: =SUM(H6:H14) -> 464549.93 | I15: =SUM(I6:I14) -> 360170.34 | J15: =SUM(J6:J14) -> 824720.27 | K15: =SUM(K6:K14) -> 0 | L15: =SUM(L6:L14) -> 464549.93 | N15: =SUM(N6:N14) -> 5.116775e+09 | P15: =SUM(P6:P14) -> 26 | Q15: =SUM(Q6:Q14) -> 264
J16: 818187
J17: =J16-J15 -> -6533.2693
G18: Sale Value | H18: Commision Percentage
G19: 0-100M | H19: 0.05
A20: Muraba Veil Furniture Pack | G20: 101M to 200M | H20: 0.0525 | J20: =D6*3 -> 11514.263 | K20: 15333 | L20: =3838*2 -> 7676 | M20: 4939
A21: Type | B21: Amount in AED | G21: 201M to 300M | H21: 0.055 | J21: =D8*4 -> 19757.803
A22: 2 Bedroom | B22: 475000 | G22: 301M to 400M | H22: 0.0575 | J22: =SUM(J20:J21) -> 31272.066
A23: 3 Bedroom | B23: 550000 | G23: 400M+ | H23: 0.06
A24: 3 Bedroom Pool | B24: 600000
A25: 3 Bedroom XL | B25: 800000
A26: 3 Bedroom Duplex | B26: 800000
A27: 4 Bedroom | B27: 850000
A28: 4 Bedroom Duplex | B28: 850000
A29: 5 Bedroom PH | B29: 1250000

Sheet Muraba Unit Wise Details 
A1: Master Unit Details
A3: Type | B3: Unit Status | C3: Unit | D3: Floor | E3: Parking count | F3: Internal Area (Sq.ft) | G3: External Area (Sq.ft) | H3: Total Area (Sq.ft) | I3: Terrace Area | J3: Sellable Area (Sq. ft) | K3: Price/Sq.ft | L3: Price | M3: Column1 | N3: Column2 | O3: Column3 | P3: Column4 | Q3: Column5 | R3: Column6
A4: =IF(Table2[[#This Row],[Unit ]]="","","2 Bedroom") -> 2 Bedroom | B4: Sold | C4: 302 | D4: 3rd | E4: =IF(Table2[[#This Row],[Unit ]]="","",_xlfn.XLOOKUP(Table2[[#This Row],[Type]],'Muraba Veil Sale Summary'!A:A,'Muraba Veil Sale Summary'!P:P)) -> 2 | F4: =IF(Table2[[#This Row],[Unit ]]="","",_xlfn.XLOOKUP(Table2[[#This Row],[Type]],'Muraba Veil Sale Summary'!$A:$A,'Muraba Veil Sale Summary'!F:F)) -> 2218.7649 | G4: =IF(Table2[[#This Row],[Unit ]]="","",_xlfn.XLOOKUP(Table2[[#This Row],[Type]],'Muraba Veil Sale Summary'!$A:$A,'Muraba Veil Sale Summary'!G:G)) -> 1619.3227 | H4: =IFERROR(F4+G4,0) -> 3838.0875 | I4: ='Launches Residences'!$U$7 -> 0.3 | J4: =IF(Table2[[#This Row],[Unit ]]="","",F4+(G4*Table2[[#This Row],[Terrace Area]])) -> 2704.5617 | K4: =_xlfn.XLOOKUP(Table2[[#This Row],[Unit ]],'Launches Residences'!$E$15:$E$71,'Launches Residences'!$I$15:$I$71) -> 4350 | L4: 11764843 | M4: =Table2[[#This Row],[Price/Sq.ft]] -> 4350 | N4: =VLOOKUP(Table2[[#This Row],[Unit ]],'[1]Muraba Unit Wise Details '!$C$4:$L$67,10,FALSE) -> 11764843 | O4: =Table2[[#This Row],[Column2]]-Table2[[#This Row],[Price]] -> 0 | P4: =Table2[[#This Row],[Price]]/Table2[[#This Row],[Total Area (Sq.ft)]] -> 3065.2879 | Q4: =Table2[[#This Row],[Price]]/Table2[[#This Row],[Sellable Area (Sq. ft)]] -> 4350
A5: =IF(Table2[[#This Row],[Unit ]]="","","2 Bedroom") -> 2 Bedroom | B5: Sold | C5: 303 | D5: 3rd | E5: =IF(Table2[[#This Row],[Unit ]]="","",_xlfn.XLOOKUP(Table2[[#This Row],[Type]],'Muraba Veil Sale Summary'!A:A,'Muraba Veil Sale Summary'!P:P)) -> 2 | F5: =IF(Table2[[#This Row],[Unit ]]="","",_xlfn.XLOOKUP(Table2[[#This Row],[Type]],'Muraba Veil Sale Summary'!$A:$A,'Muraba Veil Sale Summary'!F:F)) -> 2218.7649 | G5: =IF(Table2[[#This Row],[Unit ]]="","",_xlfn.XLOOKUP(Table2[[#This Row],[Type]],'Muraba Veil Sale Summary'!$A:$A,'Muraba Veil Sale Summary'!G:G)) -> 1619.3227 | H5: =IFERROR(F5+G5,0) -> 3838.0875 | I5: ='Launches Residences'!$U$7 -> 0.3 | J5: =IF(Table2[[#This Row],[Unit ]]="","",F5+(G5*Table2[[#This Row],[Terrace Area]])) -> 2704.5617 | K5: =_xlfn.XLOOKUP(Table2[[#This Row],[Unit ]],'Launches Residences'!$F$15:$F$71,'Launches Residences'!$J$15:$J$71) -> 4350 | L5: 11764843 | M5: =Table2[[#This Row],[Price/Sq.ft]] -> 4350 | N5: =VLOOKUP(Table2[[#This Row],[Unit ]],'[1]Muraba Unit Wise Details '!$C$4:$L$67,10,FALSE) -> 11764843 | O5: =Table2[[#This Row],[Column2]]-Table2[[#This Row],[Price]] -> 0 | P5: =Table2[[#This Row],[Price]]/Table2[[#This Row],[Total Area (Sq.ft)]] -> 3065.2879 | Q5: =Table2[[#This Row],[Price]]/Table2[[#This Row],[Sellable Area (Sq. ft)]] -> 4350
A6: =IF(Table2[[#This Row],[Unit ]]="","","2 Bedroom") -> 2 Bedroom | B6: Sold | C6: 402 | D6: 4th | E6: =IF(Table2[[#This Row],[Unit ]]="","",_xlfn.XLOOKUP(Table2[[#This Row],[Type]],'Muraba Veil Sale Summary'!A:A,'Muraba Veil Sale Summary'!P:P)) -> 2 | F6: =IF(Table2[[#This Row],[Unit ]]="","",_xlfn.XLOOKUP(Table2[[#This Row],[Type]],'Muraba Veil Sale Summary'!$A:$A,'Muraba Veil Sale Summary'!F:F)) -> 2218.7649 | G6: =IF(Table2[[#This Row],[Unit ]]="","",_xlfn.XLOOKUP(Table2[[#This Row],[Type]],'Muraba Veil Sale Summary'!$A:$A,'Muraba Veil Sale Summary'!G:G)) -> 1619.3227 | H6: =IFERROR(F6+G6,0) -> 3838.0875 | I6: ='Launches Residences'!$U$7 -> 0.3 | J6: =IF(Table2[[#This Row],[Unit ]]="","",F6+(G6*Table2[[#This Row],[Terrace Area]])) -> 2704.5617 | K6: =_xlfn.XLOOKUP(Table2[[#This Row],[Unit ]],'Launches Residences'!$E$15:$E$71,'Launches Residences'!$I$15:$I$71) -> 4227.4999 | L6: 11433534 | M6: =Table2[[#This Row],[Price/Sq.ft]] -> 4227.4999 | N6: =VLOOKUP(Table2[[#This Row],[Unit ]],'[1]Muraba Unit Wise Details '!$C$4:$L$67,10,FALSE) -> 11433534 | O6: =Table2[[#This Row],[Column2]]-Table2[[#This Row],[Price]] -> 0 | P6: =Table2[[#This Row],[Price]]/Table2[[#This Row],[Total Area (Sq.ft)]] -> 2978.9665 | Q6: =Table2[[#This Row],[Price]]/Table2[[#This Row],[Sellable Area (Sq. ft)]] -> 4227.4999
A7: =IF(Table2[[#This Row],[Unit ]]="","","2 Bedroom") -> 2 Bedroom | B7: Sold | C7: 403 | D7: 4th | E7: =IF(Table2[[#This Row],[Unit ]]="","",_xlfn.XLOOKUP(Table2[[#This Row],[Type]],'Muraba Veil Sale Summary'!A:A,'Muraba Veil Sale Summary'!P:P)) -> 2 | F7: =IF(Table2[[#This Row],[Unit ]]="","",_xlfn.XLOOKUP(Table2[[#This Row],[Type]],'Muraba Veil Sale Summary'!$A:$A,'Muraba Veil Sale Summary'!F:F)) -> 2218.7649 | G7: =IF(Table2[[#This Row],[Unit ]]="","",_xlfn.XLOOKUP(Table2[[#This Row],[Type]],'Muraba Veil Sale Summary'!$A:$A,'Muraba Veil Sale Summary'!G:G)) -> 1619.3227 | H7: =IFERROR(F7+G7,0) -> 3838.0875 | I7: ='Launches Residences'!$U$7 -> 0.3 | J7: =IF(Table2[[#This Row],[Unit ]]="","",F7+(G7*Table2[[#This Row],[Terrace Area]])) -> 2704.5617 | K7: =_xlfn.XLOOKUP(Table2[[#This Row],[Unit ]],'Launches Residences'!$F$15:$F$71,'Launches Residences'!$J$15:$J$71) -> 4449.9999 | L7: 12035299 | M7: =Table2[[#This Row],[Price/Sq.ft]] -> 4449.9999 | N7: =VLOOKUP(Table2[[#This Row],[Unit ]],'[1]Muraba Unit Wise Details '!$C$4:$L$67,10,FALSE) -> 12035299 | O7: =Table2[[#This Row],[Column2]]-Table2[[#This Row],[Price]] -> 0 | P7: =Table2[[#This Row],[Price]]/Table2[[#This Row],[Total Area (Sq.ft)]] -> 3135.7542 | Q7: =Table2[[#This Row],[Price]]/Table2[[#This Row],[Sellable Area (Sq. ft)]] -> 4449.9999
A8: =IF(Table2[[#This Row],[Unit ]]="","","2 Bedroom") -> 2 Bedroom | B8: Sold | C8: 502 | D8: 5th | E8: =IF(Table2[[#This Row],[Unit ]]="","",_xlfn.XLOOKUP(Table2[[#This Row],[Type]],'Muraba Veil Sale Summary'!A:A,'Muraba Veil Sale Summary'!P:P)) -> 2 | F8: =IF(Table2[[#This Row],[Unit ]]="","",_xlfn.XLOOKUP(Table2[[#This Row],[Type]],'Muraba Veil Sale Summary'!$A:$A,'Muraba Veil Sale Summary'!F:F)) -> 2218.7649 | G8: =IF(Table2[[#This Row],[Unit ]]="","",_xlfn.XLOOKUP(Table2[[#This Row],[Type]],'Muraba Veil Sale Summary'!$A:$A,'Muraba Veil Sale Summary'!G:G)) -> 1619.3227 | H8: =IFERROR(F8+G8,0) -> 3838.0875 | I8: ='Launches Residences'!$U$7 -> 0.3 | J8: =IF(Table2[[#This Row],[Unit ]]="","",F8+(G8*Table2[[#This Row],[Terrace Area]])) -> 2704.5617 | K8: =_xlfn.XLOOKUP(Table2[[#This Row],[Unit ]],'Launches Residences'!$E$15:$E$71,'Launches Residences'!$I$15:$I$71) -> 4550.0002 | L8: 12305756 | M8: =Table2[[#This Row],[Price/Sq.ft]] -> 4550.0002 | N8: =VLOOKUP(Table2[[#This Row],[Unit ]],'[1]Muraba Unit Wise Details '!$C$4:$L$67,10,FALSE) -> 12305756 | O8: =Table2[[#This Row],[Column2]]-Table2[[#This Row],[Price]] -> 0 | P8: =Table2[[#This Row],[Price]]/Table2[[#This Row],[Total Area (Sq.ft)]] -> 3206.2208 | Q8: =Table2[[#This Row],[Price]]/Table2[[#This Row],[Sellable Area (Sq. ft)]] -> 4550.0002
A9: =IF(Table2[[#This Row],[Unit ]]="","","2 Bedroom") -> 2 Bedroom | B9: Available | C9: 503 | D9: 5th | E9: =IF(Table2[[#This Row],[Unit ]]="","",_xlfn.XLOOKUP(Table2[[#This Row],[Type]],'Muraba Veil Sale Summary'!A:A,'Muraba Veil Sale Summary'!P:P)) -> 2 | F9: =IF(Table2[[#This Row],[Unit ]]="","",_xlfn.XLOOKUP(Table2[[#This Row],[Type]],'Muraba Veil Sale Summary'!$A:$A,'Muraba Veil Sale Summary'!F:F)) -> 2218.7649 | G9: =IF(Table2[[#This Row],[Unit ]]="","",_xlfn.XLOOKUP(Table2[[#This Row],[Type]],'Muraba Veil Sale Summary'!$A:$A,'Muraba Veil Sale Summary'!G:G)) -> 1619.3227 | H9: =IFERROR(F9+G9,0) -> 3838.0875 | I9: ='Launches Residences'!$U$7 -> 0.3 | J9: =IF(Table2[[#This Row],[Unit ]]="","",F9+(G9*Table2[[#This Row],[Terrace Area]])) -> 2704.5617 | K9: =_xlfn.XLOOKUP(Table2[[#This Row],[Unit ]],'Launches Residences'!$F$15:$F$71,'Launches Residences'!$J$15:$J$71) -> 4550.0002 | L9: =IFERROR(J9*K9,0) -> 12305756 | M9: =Table2[[#This Row],[Price/Sq.ft]] -> 4550.0002 | N9: =VLOOKUP(Table2[[#This Row],[Unit ]],'[1]Muraba Unit Wise Details '!$C$4:$L$67,10,FALSE) -> 13522808 | O9: =Table2[[#This Row],[Column2]]-Table2[[#This Row],[Price]] -> 1217052.3 | P9: =Table2[[#This Row],[Price]]/Table2[[#This Row],[Total Area (Sq.ft)]] -> 3206.2208 | Q9: =Table2[[#This Row],[Price]]/Table2[[#This Row],[Sellable Area (Sq. ft)]] -> 4550.0002
A10: =IF(Table2[[#This Row],[Unit ]]="","","2 Bedroom") -> 2 Bedroom | B10: Available | C10: 602 | D10: 6th | E10: =IF(Table2[[#This Row],[Unit ]]="","",_xlfn.XLOOKUP(Table2[[#This Row],[Type]],'Muraba Veil Sale Summary'!A:A,'Muraba Veil Sale Summary'!P:P)) -> 2 | F10: =IF(Table2[[#This Row],[Unit ]]="","",_xlfn.XLOOKUP(Table2[[#This Row],[Type]],'Muraba Veil Sale Summary'!$A:$A,'Muraba Veil Sale Summary'!F:F)) -> 2218.7649 | G10: =IF(Table2[[#This Row],[Unit ]]="","",_xlfn.XLOOKUP(Table2[[#This Row],[Type]],'Muraba Veil Sale Summary'!$A:$A,'Muraba Veil Sale Summary'!G:G)) -> 1619.3227 | H10: =IFERROR(F10+G10,0) -> 3838.0875 | I10: ='Launches Residences'!$U$7 -> 0.3 | J10: =IF(Table2[[#This Row],[Unit ]]="","",F10+(G10*Table2[[#This Row],[Terrace Area]])) -> 2704.5617 | K10: =_xlfn.XLOOKUP(Table2[[#This Row],[Unit ]],'Launches Residences'!$E$15:$E$71,'Launches Residences'!$I$15:$I$71) -> 5150 | L10: =IFERROR(J10*K10,0) -> 13928493 | M10: =Table2[[#This Row],[Price/Sq.ft]] -> 5150 | N10: =VLOOKUP(Table2[[#This Row],[Unit ]],'[1]Muraba Unit Wise Details '!$C$4:$L$67,10,FALSE) -> 13928493 | O10: =Table2[[#This Row],[Column2]]-Table2[[#This Row],[Price]] -> 0 | P10: =Table2[[#This Row],[Price]]/Table2[[#This Row],[Total Area (Sq.ft)]] -> 3629.019 | Q10: =Table2[[#This Row],[Price]]/Table2[[#This Row],[Sellable Area (Sq. ft)]] -> 5150
A11: =IF(Table2[[#This Row],[Unit ]]="","","2 Bedroom") -> 2 Bedroom | B11: Sold | C11: 603 | D11: 6th | E11: =IF(Table2[[#This Row],[Unit ]]="","",_xlfn.XLOOKUP(Table2[[#This Row],[Type]],'Muraba Veil Sale Summary'!A:A,'Muraba Veil Sale Summary'!P:P)) -> 2 | F11: =IF(Table2[[#This Row],[Unit ]]="","",_xlfn.XLOOKUP(Table2[[#This Row],[Type]],'Muraba Veil Sale Summary'!$A:$A,'Muraba Veil Sale Summary'!F:F)) -> 2218.7649 | G11: =IF(Table2[[#This Row],[Unit ]]="","",_xlfn.XLOOKUP(Table2[[#This Row],[Type]],'Muraba Veil Sale Summary'!$A:$A,'Muraba Veil Sale Summary'!G:G)) -> 1619.3227 | H11: =IFERROR(F11+G11,0) -> 3838.0875 | I11: ='Launches Residences'!$U$7 -> 0.3 | J11: =IF(Table2[[#This Row],[Unit ]]="","",F11+(G11*Table2[[#This Row],[Terrace Area]])) -> 2704.5617 | K11: =_xlfn.XLOOKUP(Table2[[#This Row],[Unit ]],'Launches Residences'!$F$15:$F$71,'Launches Residences'!$J$15:$J$71) -> 5050 | L11: 13658036 | M11: =Table2[[#This Row],[Price/Sq.ft]] -> 5050 | N11: =VLOOKUP(Table2[[#This Row],[Unit ]],'[1]Muraba Unit Wise Details '!$C$4:$L$67,10,FALSE) -> 13658036 | O11: =Table2[[#This Row],[Column2]]-Table2[[#This Row],[Price]] -> 0 | P11: =Table2[[#This Row],[Price]]/Table2[[#This Row],[Total Area (Sq.ft)]] -> 3558.5526 | Q11: =Table2[[#This Row],[Price]]/Table2[[#This Row],[Sellable Area (Sq. ft)]] -> 5050
A12: =IF(Table2[[#This Row],[Unit ]]="","","2 Bedroom") -> 2 Bedroom | B12: Sold | C12: 702 | D12: 7th | E12: =IF(Table2[[#This Row],[Unit ]]="","",_xlfn.XLOOKUP(Table2[[#This Row],[Type]],'Muraba Veil Sale Summary'!A:A,'Muraba Veil Sale Summary'!P:P)) -> 2 | F12: =IF(Table2[[#This Row],[Unit ]]="","",_xlfn.XLOOKUP(Table2[[#This Row],[Type]],'Muraba Veil Sale Summary'!$A:$A,'Muraba Veil Sale Summary'!F:F)) -> 2218.7649 | G12: =IF(Table2[[#This Row],[Unit ]]="","",_xlfn.XLOOKUP(Table2[[#This Row],[Type]],'Muraba Veil Sale Summary'!$A:$A,'Muraba Veil Sale Summary'!G:G)) -> 1619.3227 | H12: =IFERROR(F12+G12,0) -> 3838.0875 | I12: ='Launches Residences'!$U$7 -> 0.3 | J12: =IF(Table2[[#This Row],[Unit ]]="","",F12+(G12*Table2[[#This Row],[Terrace Area]])) -> 2704.5617 | K12: =_xlfn.XLOOKUP(Table2[[#This Row],[Unit ]],'Launches Residences'!$E$15:$E$71,'Launches Residences'!$I$15:$I$71) -> 4750 | L12: 12846668 | M12: =Table2[[#This Row],[Price/Sq.ft]] -> 4750 | N12: =VLOOKUP(Table2[[#This Row],[Unit ]],'[1]Muraba Unit Wise Details '!$C$4:$L$67,10,FALSE) -> 12846668 | O12: =Table2[[#This Row],[Column2]]-Table2[[#This Row],[Price]] -> 0 | P12: =Table2[[#This Row],[Price]]/Table2[[#This Row],[Total Area (Sq.ft)]] -> 3347.1534 | Q12: =Table2[[#This Row],[Price]]/Table2[[#This Row],[Sellable Area (Sq. ft)]] -> 4750
A13: =IF(Table2[[#This Row],[Unit ]]="","","2 Bedroom") -> 2 Bedroom | B13: Available | C13: 703 | D13: 7th | E13: =IF(Table2[[#This Row],[Unit ]]="","",_xlfn.XLOOKUP(Table2[[#This Row],[Type]],'Muraba Veil Sale Summary'!A:A,'Muraba Veil Sale Summary'!P:P)) -> 2 | F13: =IF(Table2[[#This Row],[Unit ]]="","",_xlfn.XLOOKUP(Table2[[#This Row],[Type]],'Muraba Veil Sale Summary'!$A:$A,'Muraba Veil Sale Summary'!F:F)) -> 2218.7649 | G13: =IF(Table2[[#This Row],[Unit ]]="","",_xlfn.XLOOKUP(Table2[[#This Row],[Type]],'Muraba Veil Sale Summary'!$A:$A,'Muraba Veil Sale Summary'!G:G)) -> 1619.3227 | H13: =IFERROR(F13+G13,0) -> 3838.0875 | I13: ='Launches Residences'!$U$7 -> 0.3 | J13: =IF(Table2[[#This Row],[Unit ]]="","",F13+(G13*Table2[[#This Row],[Terrace Area]])) -> 2704.5617 | K13: =_xlfn.XLOOKUP(Table2[[#This Row],[Unit ]],'Launches Residences'!$F$15:$F$71,'Launches Residences'!$J$15:$J$71) -> 4750 | L13: =IFERROR(J13*K13,0) -> 12846668 | M13: =Table2[[#This Row],[Price/Sq.ft]] -> 4750 | N13: =VLOOKUP(Table2[[#This Row],[Unit ]],'[1]Muraba Unit Wise Details '!$C$4:$L$67,10,FALSE) -> 14334177 | O13: =Table2[[#This Row],[Column2]]-Table2[[#This Row],[Price]] -> 1487508.9 | P13: =Table2[[#This Row],[Price]]/Table2[[#This Row],[Total Area (Sq.ft)]] -> 3347.1534 | Q13: =Table2[[#This Row],[Price]]/Table2[[#This Row],[Sellable Area (Sq. ft)]] -> 4750
A14: =IF(Table2[[#This Row],[Unit ]]="","","2 Bedroom") -> 2 Bedroom | B14: Sold | C14: 802 | D14: 8th | E14: =IF(Table2[[#This Row],[Unit ]]="","",_xlfn.XLOOKUP(Table2[[#This Row],[Type]],'Muraba Veil Sale Summary'!A:A,'Muraba Veil Sale Summary'!P:P)) -> 2 | F14: =IF(Table2[[#This Row],[Unit ]]="","",_xlfn.XLOOKUP(Table2[[#This Row],[Type]],'Muraba Veil Sale Summary'!$A:$A,'Muraba Veil Sale Summary'!F:F)) -> 2218.7649 | G14: =IF(Table2[[#This Row],[Unit ]]="","",_xlfn.XLOOKUP(Table2[[#This Row],[Type]],'Muraba Veil Sale Summary'!$A:$A,'Muraba Veil Sale Summary'!G:G)) -> 1619.3227 | H14: =IFERROR(F14+G14,0) -> 3838.0875 | I14: ='Launches Residences'!$U$7 -> 0.3 | J14: =IF(Table2[[#This Row],[Unit ]]="","",F14+(G14*Table2[[#This Row],[Terrace Area]])) -> 2704.5617 | K14: =_xlfn.XLOOKUP(Table2[[#This Row],[Unit ]],'Launches Residences'!$E$15:$E$71,'Launches Residences'!$I$15:$I$71) -> 4801.5718 | L14: 12986147 | M14: =Table2[[#This Row],[Price/Sq.ft]] -> 4801.5718 | N14: =VLOOKUP(Table2[[#This Row],[Unit ]],'[1]Muraba Unit Wise Details '!$C$4:$L$67,10,FALSE) -> 12986147 | O14: =Table2[[#This Row],[Column2]]-Table2[[#This Row],[Price]] -> 0 | P14: =Table2[[#This Row],[Price]]/Table2[[#This Row],[Total Area (Sq.ft)]] -> 3383.4943 | Q14: =Table2[[#This Row],[Price]]/Table2[[#This Row],[Sellable Area (Sq. ft)]] -> 4801.5718
A15: =IF(Table2[[#This Row],[Unit ]]="","","2 Bedroom") -> 2 Bedroom | B15: Sold | C15: 803 | D15: 8th | E15: =IF(Table2[[#This Row],[Unit ]]="","",_xlfn.XLOOKUP(Table2[[#This Row],[Type]],'Muraba Veil Sale Summary'!A:A,'Muraba Veil Sale Summary'!P:P)) -> 2 | F15: =IF(Table2[[#This Row],[Unit ]]="","",_xlfn.XLOOKUP(Table2[[#This Row],[Type]],'Muraba Veil Sale Summary'!$A:$A,'Muraba Veil Sale Summary'!F:F)) -> 2218.7649 | G15: =IF(Table2[[#This Row],[Unit ]]="","",_xlfn.XLOOKUP(Table2[[#This Row],[Type]],'Muraba Veil Sale Summary'!$A:$A,'Muraba Veil Sale Summary'!G:G)) -> 1619.3227 | H15: =IFERROR(F15+G15,0) -> 3838.0875 | I15: ='Launches Residences'!$U$7 -> 0.3 | J15: =IF(Table2[[#This Row],[Unit ]]="","",F15+(G15*Table2[[#This Row],[Terrace Area]])) -> 2704.5617 | K15: =_xlfn.XLOOKUP(Table2[[#This Row],[Unit ]],'Launches Residences'!$F$15:$F$71,'Launches Residences'!$J$15:$J$71) -> 4801.5718 | L15: 12986147 | M15: =Table2[[#This Row],[Price/Sq.ft]] -> 4801.5718 | N15: =VLOOKUP(Table2[[#This Row],[Unit ]],'[1]Muraba Unit Wise Details '!$C$4:$L$67,10,FALSE) -> 12986147 | O15: =Table2[[#This Row],[Column2]]-Table2[[#This Row],[Price]] -> 0 | P15: =Table2[[#This Row],[Price]]/Table2[[#This Row],[Total Area (Sq.ft)]] -> 3383.4943 | Q15: =Table2[[#This Row],[Price]]/Table2[[#This Row],[Sellable Area (Sq. ft)]] -> 4801.5718
A16: =IF(Table2[[#This Row],[Unit ]]="","","2 Bedroom") -> 2 Bedroom | B16: Available | C16: 902 | D16: 9th | E16: =IF(Table2[[#This Row],[Unit ]]="","",_xlfn.XLOOKUP(Table2[[#This Row],[Type]],'Muraba Veil Sale Summary'!A:A,'Muraba Veil Sale Summary'!P:P)) -> 2 | F16: =IF(Table2[[#This Row],[Unit ]]="","",_xlfn.XLOOKUP(Table2[[#This Row],[Type]],'Muraba Veil Sale Summary'!$A:$A,'Muraba Veil Sale Summary'!F:F)) -> 2218.7649 | G16: =IF(Table2[[#This Row],[Unit ]]="","",_xlfn.XLOOKUP(Table2[[#This Row],[Type]],'Muraba Veil Sale Summary'!$A:$A,'Muraba Veil Sale Summary'!G:G)) -> 1619.3227 | H16: =IFERROR(F16+G16,0) -> 3838.0875 | I16: ='Launches Residences'!$U$7 -> 0.3 | J16: =IF(Table2[[#This Row],[Unit ]]="","",F16+(G16*Table2[[#This Row],[Terrace Area]])) -> 2704.5617 | K16: =_xlfn.XLOOKUP(Table2[[#This Row],[Unit ]],'Launches Residences'!$E$15:$E$71,'Launches Residences'!$I$15:$I$71) -> 5600 | L16: =IFERROR(J16*K16,0) -> 15145545 | M16: =Table2[[#This Row],[Price/Sq.ft]] -> 5600 | N16: =VLOOKUP(Table2[[#This Row],[Unit ]],'[1]Muraba Unit Wise Details '!$C$4:$L$67,10,FALSE) -> 15145545 | O16: =Table2[[#This Row],[Column2]]-Table2[[#This Row],[Price]] -> 0 | P16: =Table2[[#This Row],[Price]]/Table2[[#This Row],[Total Area (Sq.ft)]] -> 3946.1177 | Q16: =Table2[[#This Row],[Price]]/Table2[[#This Row],[Sellable Area (Sq. ft)]] -> 5600
A17: =IF(Table2[[#This Row],[Unit ]]="","","2 Bedroom") -> 2 Bedroom | B17: Available | C17: 903 | D17: 9th | E17: =IF(Table2[[#This Row],[Unit ]]="","",_xlfn.XLOOKUP(Table2[[#This Row],[Type]],'Muraba Veil Sale Summary'!A:A,'Muraba Veil Sale Summary'!P:P)) -> 2 | F17: =IF(Table2[[#This Row],[Unit ]]="","",_xlfn.XLOOKUP(Table2[[#This Row],[Type]],'Muraba Veil Sale Summary'!$A:$A,'Muraba Veil Sale Summary'!F:F)) -> 2218.7649 | G17: =IF(Table2[[#This Row],[Unit ]]="","",_xlfn.XLOOKUP(Table2[[#This Row],[Type]],'Muraba Veil Sale Summary'!$A:$A,'Muraba Veil Sale Summary'!G:G)) -> 1619.3227 | H17: =IFERROR(F17+G17,0) -> 3838.0875 | I17: ='Launches Residences'!$U$7 -> 0.3 | J17: =IF(Table2[[#This Row],[Unit ]]="","",F17+(G17*Table2[[#This Row],[Terrace Area]])) -> 2704.5617 | K17: =_xlfn.XLOOKUP(Table2[[#This Row],[Unit ]],'Launches Residences'!$F$15:$F$71,'Launches Residences'!$J$15:$J$71) -> 5600 | L17: =IFERROR(J17*K17,0) -> 15145545 | M17: =Table2[[#This Row],[Price/Sq.ft]] -> 5600 | N17: =VLOOKUP(Table2[[#This Row],[Unit ]],'[1]Muraba Unit Wise Details '!$C$4:$L$67,10,FALSE) -> 15145545 | O17: =Table2[[#This Row],[Column2]]-Table2[[#This Row],[Price]] -> 0 | P17: =Table2[[#This Row],[Price]]/Table2[[#This Row],[Total Area (Sq.ft)]] -> 3946.1177 | Q17: =Table2[[#This Row],[Price]]/Table2[[#This Row],[Sellable Area (Sq. ft)]] -> 5600
A18: =IF(Table2[[#This Row],[Unit ]]="","","2 Bedroom") -> 2 Bedroom | B18: Sold | C18: 1102 | D18: 11th | E18: =IF(Table2[[#This Row],[Unit ]]="","",_xlfn.XLOOKUP(Table2[[#This Row],[Type]],'Muraba Veil Sale Summary'!A:A,'Muraba Veil Sale Summary'!P:P)) -> 2 | F18: =IF(Table2[[#This Row],[Unit ]]="","",_xlfn.XLOOKUP(Table2[[#This Row],[Type]],'Muraba Veil Sale Summary'!$A:$A,'Muraba Veil Sale Summary'!F:F)) -> 2218.7649 | G18: =IF(Table2[[#This Row],[Unit ]]="","",_xlfn.XLOOKUP(Table2[[#This Row],[Type]],'Muraba Veil Sale Summary'!$A:$A,'Muraba Veil Sale Summary'!G:G)) -> 1619.3227 | H18: =IFERROR(F18+G18,0) -> 3838.0875 | I18: ='Launches Residences'!$U$7 -> 0.3 | J18: =IF(Table2[[#This Row],[Unit ]]="","",F18+(G18*Table2[[#This Row],[Terrace Area]])) -> 2704.5617 | K18: =_xlfn.XLOOKUP(Table2[[#This Row],[Unit ]],'Launches Residences'!$E$15:$E$71,'Launches Residences'!$I$15:$I$71) -> 5050 | L18: 13658036 | M18: =Table2[[#This Row],[Price/Sq.ft]] -> 5050 | N18: =VLOOKUP(Table2[[#This Row],[Unit ]],'[1]Muraba Unit Wise Details '!$C$4:$L$67,10,FALSE) -> 13658036 | O18: =Table2[[#This Row],[Column2]]-Table2[[#This Row],[Price]] -> 0 | P18: =Table2[[#This Row],[Price]]/Table2[[#This Row],[Total Area (Sq.ft)]] -> 3558.5526 | Q18: =Table2[[#This Row],[Price]]/Table2[[#This Row],[Sellable Area (Sq. ft)]] -> 5050
A19: =IF(Table2[[#This Row],[Unit ]]="","","2 Bedroom") -> 2 Bedroom | B19: Bank Locked | C19: 1103 | D19: 11th | E19: =IF(Table2[[#This Row],[Unit ]]="","",_xlfn.XLOOKUP(Table2[[#This Row],[Type]],'Muraba Veil Sale Summary'!A:A,'Muraba Veil Sale Summary'!P:P)) -> 2 | F19: =IF(Table2[[#This Row],[Unit ]]="","",_xlfn.XLOOKUP(Table2[[#This Row],[Type]],'Muraba Veil Sale Summary'!$A:$A,'Muraba Veil Sale Summary'!F:F)) -> 2218.7649 | G19: =IF(Table2[[#This Row],[Unit ]]="","",_xlfn.XLOOKUP(Table2[[#This Row],[Type]],'Muraba Veil Sale Summary'!$A:$A,'Muraba Veil Sale Summary'!G:G)) -> 1619.3227 | H19: =IFERROR(F19+G19,0) -> 3838.0875 | I19: ='Launches Residences'!$U$7 -> 0.3 | J19: =IF(Table2[[#This Row],[Unit ]]="","",F19+(G19*Table2[[#This Row],[Terrace Area]])) -> 2704.5617 | K19: =_xlfn.XLOOKUP(Table2[[#This Row],[Unit ]],'Launches Residences'!$F$15:$F$71,'Launches Residences'!$J$15:$J$71) -> 5050 | L19: =IFERROR(J19*K19,0) -> 13658036 | M19: =Table2[[#This Row],[Price/Sq.ft]] -> 5050 | N19: =VLOOKUP(Table2[[#This Row],[Unit ]],'[1]Muraba Unit Wise Details '!$C$4:$L$67,10,FALSE) -> 15551230 | O19: =Table2[[#This Row],[Column2]]-Table2[[#This Row],[Price]] -> 1893193.2 | P19: =Table2[[#This Row],[Price]]/Table2[[#This Row],[Total Area (Sq.ft)]] -> 3558.5526 | Q19: =Table2[[#This Row],[Price]]/Table2[[#This Row],[Sellable Area (Sq. ft)]] -> 5050
A20: =IF(Table2[[#This Row],[Unit ]]="","","2 Bedroom") -> 2 Bedroom | B20: Available | C20: 1202 | D20: 12th | E20: =IF(Table2[[#This Row],[Unit ]]="","",_xlfn.XLOOKUP(Table2[[#This Row],[Type]],'Muraba Veil Sale Summary'!A:A,'Muraba Veil Sale Summary'!P:P)) -> 2 | F20: =IF(Table2[[#This Row],[Unit ]]="","",_xlfn.XLOOKUP(Table2[[#This Row],[Type]],'Muraba Veil Sale Summary'!$A:$A,'Muraba Veil Sale Summary'!F:F)) -> 2218.7649 | G20: =IF(Table2[[#This Row],[Unit ]]="","",_xlfn.XLOOKUP(Table2[[#This Row],[Type]],'Muraba Veil Sale Summary'!$A:$A,'Muraba Veil Sale Summary'!G:G)) -> 1619.3227 | H20: =IFERROR(F20+G20,0) -> 3838.0875 | I20: ='Launches Residences'!$U$7 -> 0.3 | J20: =IF(Table2[[#This Row],[Unit ]]="","",F20+(G20*Table2[[#This Row],[Terrace Area]])) -> 2704.5617 | K20: =_xlfn.XLOOKUP(Table2[[#This Row],[Unit ]],'Launches Residences'!$E$15:$E$71,'Launches Residences'!$I$15:$I$71) -> 5900 | L20: =IFERROR(J20*K20,0) -> 15956914 | M20: =Table2[[#This Row],[Price/Sq.ft]] -> 5900 | N20: =VLOOKUP(Table2[[#This Row],[Unit ]],'[1]Muraba Unit Wise Details '!$C$4:$L$67,10,FALSE) -> 15956914 | O20: =Table2[[#This Row],[Column2]]-Table2[[#This Row],[Price]] -> 0 | P20: =Table2[[#This Row],[Price]]/Table2[[#This Row],[Total Area (Sq.ft)]] -> 4157.5169 | Q20: =Table2[[#This Row],[Price]]/Table2[[#This Row],[Sellable Area (Sq. ft)]] -> 5900
A21: =IF(Table2[[#This Row],[Unit ]]="","","2 Bedroom") -> 2 Bedroom | B21: Available | C21: 1203 | D21: 12th | E21: =IF(Table2[[#This Row],[Unit ]]="","",_xlfn.XLOOKUP(Table2[[#This Row],[Type]],'Muraba Veil Sale Summary'!A:A,'Muraba Veil Sale Summary'!P:P)) -> 2 | F21: =IF(Table2[[#This Row],[Unit ]]="","",_xlfn.XLOOKUP(Table2[[#This Row],[Type]],'Muraba Veil Sale Summary'!$A:$A,'Muraba Veil Sale Summary'!F:F)) -> 2218.7649 | G21: =IF(Table2[[#This Row],[Unit ]]="","",_xlfn.XLOOKUP(Table2[[#This Row],[Type]],'Muraba Veil Sale Summary'!$A:$A,'Muraba Veil Sale Summary'!G:G)) -> 1619.3227 | H21: =IFERROR(F21+G21,0) -> 3838.0875 | I21: ='Launches Residences'!$U$7 -> 0.3 | J21: =IF(Table2[[#This Row],[Unit ]]="","",F21+(G21*Table2[[#This Row],[Terrace Area]])) -> 2704.5617 | K21: =_xlfn.XLOOKUP(Table2[[#This Row],[Unit ]],'Launches Residences'!$F$15:$F$71,'Launches Residences'!$J$15:$J$71) -> 5900 | L21: =IFERROR(J21*K21,0) -> 15956914 | M21: =Table2[[#This Row],[Price/Sq.ft]] -> 5900 | N21: =VLOOKUP(Table2[[#This Row],[Unit ]],'[1]Muraba Unit Wise Details '!$C$4:$L$67,10,FALSE) -> 15956914 | O21: =Table2[[#This Row],[Column2]]-Table2[[#This Row],[Price]] -> 0 | P21: =Table2[[#This Row],[Price]]/Table2[[#This Row],[Total Area (Sq.ft)]] -> 4157.5169 | Q21: =Table2[[#This Row],[Price]]/Table2[[#This Row],[Sellable Area (Sq. ft)]] -> 5900
A22: =IF(Table2[[#This Row],[Unit ]]="","","2 Bedroom") -> 2 Bedroom | B22: Available | C22: 1302 | D22: 13th | E22: =IF(Table2[[#This Row],[Unit ]]="","",_xlfn.XLOOKUP(Table2[[#This Row],[Type]],'Muraba Veil Sale Summary'!A:A,'Muraba Veil Sale Summary'!P:P)) -> 2 | F22: =IF(Table2[[#This Row],[Unit ]]="","",_xlfn.XLOOKUP(Table2[[#This Row],[Type]],'Muraba Veil Sale Summary'!$A:$A,'Muraba Veil Sale Summary'!F:F)) -> 2218.7649 | G22: =IF(Table2[[#This Row],[Unit ]]="","",_xlfn.XLOOKUP(Table2[[#This Row],[Type]],'Muraba Veil Sale Summary'!$A:$A,'Muraba Veil Sale Summary'!G:G)) -> 1619.3227 | H22: =IFERROR(F22+G22,0) -> 3838.0875 | I22: ='Launches Residences'!$U$7 -> 0.3 | J22: =IF(Table2[[#This Row],[Unit ]]="","",F22+(G22*Table2[[#This Row],[Terrace Area]])) -> 2704.5617 | K22: =_xlfn.XLOOKUP(Table2[[#This Row],[Unit ]],'Launches Residences'!$E$15:$E$71,'Launches Residences'!$I$15:$I$71) -> 6050 | L22: =IFERROR(J22*K22,0) -> 16362598 | M22: =Table2[[#This Row],[Price/Sq.ft]] -> 6050 | N22: =VLOOKUP(Table2[[#This Row],[Unit ]],'[1]Muraba Unit Wise Details '!$C$4:$L$67,10,FALSE) -> 16362598 | O22: =Table2[[#This Row],[Column2]]-Table2[[#This Row],[Price]] -> 0 | P22: =Table2[[#This Row],[Price]]/Table2[[#This Row],[Total Area (Sq.ft)]] -> 4263.2165 | Q22: =Table2[[#This Row],[Price]]/Table2[[#This Row],[Sellable Area (Sq. ft)]] -> 6050
A23: =IF(Table2[[#This Row],[Unit ]]="","","2 Bedroom") -> 2 Bedroom | B23: Available | C23: 1303 | D23: 13th | E23: =IF(Table2[[#This Row],[Unit ]]="","",_xlfn.XLOOKUP(Table2[[#This Row],[Type]],'Muraba Veil Sale Summary'!A:A,'Muraba Veil Sale Summary'!P:P)) -> 2 | F23: =IF(Table2[[#This Row],[Unit ]]="","",_xlfn.XLOOKUP(Table2[[#This Row],[Type]],'Muraba Veil Sale Summary'!$A:$A,'Muraba Veil Sale Summary'!F:F)) -> 2218.7649 | G23: =IF(Table2[[#This Row],[Unit ]]="","",_xlfn.XLOOKUP(Table2[[#This Row],[Type]],'Muraba Veil Sale Summary'!$A:$A,'Muraba Veil Sale Summary'!G:G)) -> 1619.3227 | H23: =IFERROR(F23+G23,0) -> 3838.0875 | I23: ='Launches Residences'!$U$7 -> 0.3 | J23: =IF(Table2[[#This Row],[Unit ]]="","",F23+(G23*Table2[[#This Row],[Terrace Area]])) -> 2704.5617 | K23: =_xlfn.XLOOKUP(Table2[[#This Row],[Unit ]],'Launches Residences'!$F$15:$F$71,'Launches Residences'!$J$15:$J$71) -> 6050 | L23: =IFERROR(J23*K23,0) -> 16362598 | M23: =Table2[[#This Row],[Price/Sq.ft]] -> 6050 | N23: =VLOOKUP(Table2[[#This Row],[Unit ]],'[1]Muraba Unit Wise Details '!$C$4:$L$67,10,FALSE) -> 16362598 | O23: =Table2[[#This Row],[Column2]]-Table2[[#This Row],[Price]] -> 0 | P23: =Table2[[#This Row],[Price]]/Table2[[#This Row],[Total Area (Sq.ft)]] -> 4263.2165 | Q23: =Table2[[#This Row],[Price]]/Table2[[#This Row],[Sellable Area (Sq. ft)]] -> 6050
A24: =IF(Table2[[#This Row],[Unit ]]="","","2 Bedroom") -> 2 Bedroom | B24: Available | C24: 1402 | D24: 14th | E24: =IF(Table2[[#This Row],[Unit ]]="","",_xlfn.XLOOKUP(Table2[[#This Row],[Type]],'Muraba Veil Sale Summary'!A:A,'Muraba Veil Sale Summary'!P:P)) -> 2 | F24: =IF(Table2[[#This Row],[Unit ]]="","",_xlfn.XLOOKUP(Table2[[#This Row],[Type]],'Muraba Veil Sale Summary'!$A:$A,'Muraba Veil Sale Summary'!F:F)) -> 2218.7649 | G24: =IF(Table2[[#This Row],[Unit ]]="","",_xlfn.XLOOKUP(Table2[[#This Row],[Type]],'Muraba Veil Sale Summary'!$A:$A,'Muraba Veil Sale Summary'!G:G)) -> 1619.3227 | H24: =IFERROR(F24+G24,0) -> 3838.0875 | I24: ='Launches Residences'!$U$7 -> 0.3 | J24: =IF(Table2[[#This Row],[Unit ]]="","",F24+(G24*Table2[[#This Row],[Terrace Area]])) -> 2704.5617 | K24: =_xlfn.XLOOKUP(Table2[[#This Row],[Unit ]],'Launches Residences'!$E$15:$E$71,'Launches Residences'!$I$15:$I$71) -> 6200 | L24: =IFERROR(J24*K24,0) -> 16768282 | M24: =Table2[[#This Row],[Price/Sq.ft]] -> 6200 | N24: =VLOOKUP(Table2[[#This Row],[Unit ]],'[1]Muraba Unit Wise Details '!$C$4:$L$67,10,FALSE) -> 16768282 | O24: =Table2[[#This Row],[Column2]]-Table2[[#This Row],[Price]] -> 0 | P24: =Table2[[#This Row],[Price]]/Table2[[#This Row],[Total Area (Sq.ft)]] -> 4368.9161 | Q24: =Table2[[#This Row],[Price]]/Table2[[#This Row],[Sellable Area (Sq. ft)]] -> 6200
A25: =IF(Table2[[#This Row],[Unit ]]="","","2 Bedroom") -> 2 Bedroom | B25: Available | C25: 1403 | D25: 14th | E25: =IF(Table2[[#This Row],[Unit ]]="","",_xlfn.XLOOKUP(Table2[[#This Row],[Type]],'Muraba Veil Sale Summary'!A:A,'Muraba Veil Sale Summary'!P:P)) -> 2 | F25: =IF(Table2[[#This Row],[Unit ]]="","",_xlfn.XLOOKUP(Table2[[#This Row],[Type]],'Muraba Veil Sale Summary'!$A:$A,'Muraba Veil Sale Summary'!F:F)) -> 2218.7649 | G25: =IF(Table2[[#This Row],[Unit ]]="","",_xlfn.XLOOKUP(Table2[[#This Row],[Type]],'Muraba Veil Sale Summary'!$A:$A,'Muraba Veil Sale Summary'!G:G)) -> 1619.3227 | H25: =IFERROR(F25+G25,0) -> 3838.0875 | I25: ='Launches Residences'!$U$7 -> 0.3 | J25: =IF(Table2[[#This Row],[Unit ]]="","",F25+(G25*Table2[[#This Row],[Terrace Area]])) -> 2704.5617 | K25: =_xlfn.XLOOKUP(Table2[[#This Row],[Unit ]],'Launches Residences'!$F$15:$F$71,'Launches Residences'!$J$15:$J$71) -> 6200 | L25: =IFERROR(J25*K25,0) -> 16768282 | M25: =Table2[[#This Row],[Price/Sq.ft]] -> 6200 | N25: =VLOOKUP(Table2[[#This Row],[Unit ]],'[1]Muraba Unit Wise Details '!$C$4:$L$67,10,FALSE) -> 16768282 | O25: =Table2[[#This Row],[Column2]]-Table2[[#This Row],[Price]] -> 0 | P25: =Table2[[#This Row],[Price]]/Table2[[#This Row],[Total Area (Sq.ft)]] -> 4368.9161 | Q25: =Table2[[#This Row],[Price]]/Table2[[#This Row],[Sellable Area (Sq. ft)]] -> 6200
A26: =IF(Table2[[#This Row],[Unit ]]="","","2 Bedroom") -> 2 Bedroom | B26: Bank Locked | C26: 1502 | D26: 15th | E26: =IF(Table2[[#This Row],[Unit ]]="","",_xlfn.XLOOKUP(Table2[[#This Row],[Type]],'Muraba Veil Sale Summary'!A:A,'Muraba Veil Sale Summary'!P:P)) -> 2 | F26: =IF(Table2[[#This Row],[Unit ]]="","",_xlfn.XLOOKUP(Table2[[#This Row],[Type]],'Muraba Veil Sale Summary'!$A:$A,'Muraba Veil Sale Summary'!F:F)) -> 2218.7649 | G26: =IF(Table2[[#This Row],[Unit ]]="","",_xlfn.XLOOKUP(Table2[[#This Row],[Type]],'Muraba Veil Sale Summary'!$A:$A,'Muraba Veil Sale Summary'!G:G)) -> 1619.3227 | H26: =IFERROR(F26+G26,0) -> 3838.0875 | I26: ='Launches Residences'!$U$7 -> 0.3 | J26: =IF(Table2[[#This Row],[Unit ]]="","",F26+(G26*Table2[[#This Row],[Terrace Area]])) -> 2704.5617 | K26: =_xlfn.XLOOKUP(Table2[[#This Row],[Unit ]],'Launches Residences'!$E$15:$E$71,'Launches Residences'!$I$15:$I$71) -> 6350 | L26: =IFERROR(J26*K26,0) -> 17173967 | M26: =Table2[[#This Row],[Price/Sq.ft]] -> 6350 | N26: =VLOOKUP(Table2[[#This Row],[Unit ]],'[1]Muraba Unit Wise Details '!$C$4:$L$67,10,FALSE) -> 17173967 | O26: =Table2[[#This Row],[Column2]]-Table2[[#This Row],[Price]] -> 0 | P26: =Table2[[#This Row],[Price]]/Table2[[#This Row],[Total Area (Sq.ft)]] -> 4474.6156 | Q26: =Table2[[#This Row],[Price]]/Table2[[#This Row],[Sellable Area (Sq. ft)]] -> 6350
A27: =IF(Table2[[#This Row],[Unit ]]="","","2 Bedroom") -> 2 Bedroom | B27: Bank Locked | C27: 1503 | D27: 15th | E27: =IF(Table2[[#This Row],[Unit ]]="","",_xlfn.XLOOKUP(Table2[[#This Row],[Type]],'Muraba Veil Sale Summary'!A:A,'Muraba Veil Sale Summary'!P:P)) -> 2 | F27: =IF(Table2[[#This Row],[Unit ]]="","",_xlfn.XLOOKUP(Table2[[#This Row],[Type]],'Muraba Veil Sale Summary'!$A:$A,'Muraba Veil Sale Summary'!F:F)) -> 2218.7649 | G27: =IF(Table2[[#This Row],[Unit ]]="","",_xlfn.XLOOKUP(Table2[[#This Row],[Type]],'Muraba Veil Sale Summary'!$A:$A,'Muraba Veil Sale Summary'!G:G)) -> 1619.3227 | H27: =IFERROR(F27+G27,0) -> 3838.0875 | I27: ='Launches Residences'!$U$7 -> 0.3 | J27: =IF(Table2[[#This Row],[Unit ]]="","",F27+(G27*Table2[[#This Row],[Terrace Area]])) -> 2704.5617 | K27: =_xlfn.XLOOKUP(Table2[[#This Row],[Unit ]],'Launches Residences'!$F$15:$F$71,'Launches Residences'!$J$15:$J$71) -> 6350 | L27: =IFERROR(J27*K27,0) -> 17173967 | M27: =Table2[[#This Row],[Price/Sq.ft]] -> 6350 | N27: =VLOOKUP(Table2[[#This Row],[Unit ]],'[1]Muraba Unit Wise Details '!$C$4:$L$67,10,FALSE) -> 17173967 | O27: =Table2[[#This Row],[Column2]]-Table2[[#This Row],[Price]] -> 0 | P27: =Table2[[#This Row],[Price]]/Table2[[#This Row],[Total Area (Sq.ft)]] -> 4474.6156 | Q27: =Table2[[#This Row],[Price]]/Table2[[#This Row],[Sellable Area (Sq. ft)]] -> 6350
A28: =IF(Table2[[#This Row],[Unit ]]="","","2 Bedroom") -> 2 Bedroom | B28: Available | C28: 1602 | D28: 16th | E28: =IF(Table2[[#This Row],[Unit ]]="","",_xlfn.XLOOKUP(Table2[[#This Row],[Type]],'Muraba Veil Sale Summary'!A:A,'Muraba Veil Sale Summary'!P:P)) -> 2 | F28: =IF(Table2[[#This Row],[Unit ]]="","",_xlfn.XLOOKUP(Table2[[#This Row],[Type]],'Muraba Veil Sale Summary'!$A:$A,'Muraba Veil Sale Summary'!F:F)) -> 2218.7649 | G28: =IF(Table2[[#This Row],[Unit ]]="","",_xlfn.XLOOKUP(Table2[[#This Row],[Type]],'Muraba Veil Sale Summary'!$A:$A,'Muraba Veil Sale Summary'!G:G)) -> 1619.3227 | H28: =IFERROR(F28+G28,0) -> 3838.0875 | I28: ='Launches Residences'!$U$7 -> 0.3 | J28: =IF(Table2[[#This Row],[Unit ]]="","",F28+(G28*Table2[[#This Row],[Terrace Area]])) -> 2704.5617 | K28: =_xlfn.XLOOKUP(Table2[[#This Row],[Unit ]],'Launches Residences'!$E$15:$E$71,'Launches Residences'!$I$15:$I$71) -> 6500 | L28: =IFERROR(J28*K28,0) -> 17579651 | M28: =Table2[[#This Row],[Price/Sq.ft]] -> 6500 | N28: =VLOOKUP(Table2[[#This Row],[Unit ]],'[1]Muraba Unit Wise Details '!$C$4:$L$67,10,FALSE) -> 17579651 | O28: =Table2[[#This Row],[Column2]]-Table2[[#This Row],[Price]] -> 0 | P28: =Table2[[#This Row],[Price]]/Table2[[#This Row],[Total Area (Sq.ft)]] -> 4580.3152 | Q28: =Table2[[#This Row],[Price]]/Table2[[#This Row],[Sellable Area (Sq. ft)]] -> 6500
A29: =IF(Table2[[#This Row],[Unit ]]="","","2 Bedroom") -> 2 Bedroom | B29: Available | C29: 1603 | D29: 16th | E29: =IF(Table2[[#This Row],[Unit ]]="","",_xlfn.XLOOKUP(Table2[[#This Row],[Type]],'Muraba Veil Sale Summary'!A:A,'Muraba Veil Sale Summary'!P:P)) -> 2 | F29: =IF(Table2[[#This Row],[Unit ]]="","",_xlfn.XLOOKUP(Table2[[#This Row],[Type]],'Muraba Veil Sale Summary'!$A:$A,'Muraba Veil Sale Summary'!F:F)) -> 2218.7649 | G29: =IF(Table2[[#This Row],[Unit ]]="","",_xlfn.XLOOKUP(Table2[[#This Row],[Type]],'Muraba Veil Sale Summary'!$A:$A,'Muraba Veil Sale Summary'!G:G)) -> 1619.3227 | H29: =IFERROR(F29+G29,0) -> 3838.0875 | I29: ='Launches Residences'!$U$7 -> 0.3 | J29: =IF(Table2[[#This Row],[Unit ]]="","",F29+(G29*Table2[[#This Row],[Terrace Area]])) -> 2704.5617 | K29: =_xlfn.XLOOKUP(Table2[[#This Row],[Unit ]],'Launches Residences'!$F$15:$F$71,'Launches Residences'!$J$15:$J$71) -> 6500 | L29: =IFERROR(J29*K29,0) -> 17579651 | M29: =Table2[[#This Row],[Price/Sq.ft]] -> 6500 | N29: =VLOOKUP(Table2[[#This Row],[Unit ]],'[1]Muraba Unit Wise Details '!$C$4:$L$67,10,FALSE) -> 17579651 | O29: =Table2[[#This Row],[Column2]]-Table2[[#This Row],[Price]] -> 0 | P29: =Table2[[#This Row],[Price]]/Table2[[#This Row],[Total Area (Sq.ft)]] -> 4580.3152 | Q29: =Table2[[#This Row],[Price]]/Table2[[#This Row],[Sellable Area (Sq. ft)]] -> 6500
A30: =IF(Table2[[#This Row],[Unit ]]="","","2 Bedroom") -> 2 Bedroom | B30: Sold | C30: 1702 | D30: 17th | E30: =IF(Table2[[#This Row],[Unit ]]="","",_xlfn.XLOOKUP(Table2[[#This Row],[Type]],'Muraba Veil Sale Summary'!A:A,'Muraba Veil Sale Summary'!P:P)) -> 2 | F30: =IF(Table2[[#This Row],[Unit ]]="","",_xlfn.XLOOKUP(Table2[[#This Row],[Type]],'Muraba Veil Sale Summary'!$A:$A,'Muraba Veil Sale Summary'!F:F)) -> 2218.7649 | G30: =IF(Table2[[#This Row],[Unit ]]="","",_xlfn.XLOOKUP(Table2[[#This Row],[Type]],'Muraba Veil Sale Summary'!$A:$A,'Muraba Veil Sale Summary'!G:G)) -> 1619.3227 | H30: =IFERROR(F30+G30,0) -> 3838.0875 | I30: ='Launches Residences'!$U$7 -> 0.3 | J30: =IF(Table2[[#This Row],[Unit ]]="","",F30+(G30*Table2[[#This Row],[Terrace Area]])) -> 2704.5617 | K30: =_xlfn.XLOOKUP(Table2[[#This Row],[Unit ]],'Launches Residences'!$E$15:$E$71,'Launches Residences'!$I$15:$I$71) -> 5541.346 | L30: 14986912 | M30: =Table2[[#This Row],[Price/Sq.ft]] -> 5541.346 | N30: =VLOOKUP(Table2[[#This Row],[Unit ]],'[1]Muraba Unit Wise Details '!$C$4:$L$67,10,FALSE) -> 14986912 | O30: =Table2[[#This Row],[Column2]]-Table2[[#This Row],[Price]] -> 0 | P30: =Table2[[#This Row],[Price]]/Table2[[#This Row],[Total Area (Sq.ft)]] -> 3904.7864 | Q30: =Table2[[#This Row],[Price]]/Table2[[#This Row],[Sellable Area (Sq. ft)]] -> 5541.346
A31: =IF(Table2[[#This Row],[Unit ]]="","","2 Bedroom") -> 2 Bedroom | B31: Available | C31: 1703 | D31: 17th | E31: =IF(Table2[[#This Row],[Unit ]]="","",_xlfn.XLOOKUP(Table2[[#This Row],[Type]],'Muraba Veil Sale Summary'!A:A,'Muraba Veil Sale Summary'!P:P)) -> 2 | F31: =IF(Table2[[#This Row],[Unit ]]="","",_xlfn.XLOOKUP(Table2[[#This Row],[Type]],'Muraba Veil Sale Summary'!$A:$A,'Muraba Veil Sale Summary'!F:F)) -> 2218.7649 | G31: =IF(Table2[[#This Row],[Unit ]]="","",_xlfn.XLOOKUP(Table2[[#This Row],[Type]],'Muraba Veil Sale Summary'!$A:$A,'Muraba Veil Sale Summary'!G:G)) -> 1619.3227 | H31: =IFERROR(F31+G31,0) -> 3838.0875 | I31: ='Launches Residences'!$U$7 -> 0.3 | J31: =IF(Table2[[#This Row],[Unit ]]="","",F31+(G31*Table2[[#This Row],[Terrace Area]])) -> 2704.5617 | K31: =_xlfn.XLOOKUP(Table2[[#This Row],[Unit ]],'Launches Residences'!$F$15:$F$71,'Launches Residences'!$J$15:$J$71) -> 6650 | L31: =IFERROR(J31*K31,0) -> 17985335 | M31: =Table2[[#This Row],[Price/Sq.ft]] -> 6650 | N31: =VLOOKUP(Table2[[#This Row],[Unit ]],'[1]Muraba Unit Wise Details '!$C$4:$L$67,10,FALSE) -> 17985335 | O31: =Table2[[#This Row],[Column2]]-Table2[[#This Row],[Price]] -> 0 | P31: =Table2[[#This Row],[Price]]/Table2[[#This Row],[Total Area (Sq.ft)]] -> 4686.0148 | Q31: =Table2[[#This Row],[Price]]/Table2[[#This Row],[Sellable Area (Sq. ft)]] -> 6650
A32: =IF(Table2[[#This Row],[Unit ]]="","","2 Bedroom") -> 2 Bedroom | B32: Available | C32: 1802 | D32: 18th | E32: =IF(Table2[[#This Row],[Unit ]]="","",_xlfn.XLOOKUP(Table2[[#This Row],[Type]],'Muraba Veil Sale Summary'!A:A,'Muraba Veil Sale Summary'!P:P)) -> 2 | F32: =IF(Table2[[#This Row],[Unit ]]="","",_xlfn.XLOOKUP(Table2[[#This Row],[Type]],'Muraba Veil Sale Summary'!$A:$A,'Muraba Veil Sale Summary'!F:F)) -> 2218.7649 | G32: =IF(Table2[[#This Row],[Unit ]]="","",_xlfn.XLOOKUP(Table2[[#This Row],[Type]],'Muraba Veil Sale Summary'!$A:$A,'Muraba Veil Sale Summary'!G:G)) -> 1619.3227 | H32: =IFERROR(F32+G32,0) -> 3838.0875 | I32: ='Launches Residences'!$U$7 -> 0.3 | J32: =IF(Table2[[#This Row],[Unit ]]="","",F32+(G32*Table2[[#This Row],[Terrace Area]])) -> 2704.5617 | K32: =_xlfn.XLOOKUP(Table2[[#This Row],[Unit ]],'Launches Residences'!$E$15:$E$71,'Launches Residences'!$I$15:$I$71) -> 6800 | L32: =IFERROR(J32*K32,0) -> 18391019 | M32: =Table2[[#This Row],[Price/Sq.ft]] -> 6800 | N32: =VLOOKUP(Table2[[#This Row],[Unit ]],'[1]Muraba Unit Wise Details '!$C$4:$L$67,10,FALSE) -> 18391019 | O32: =Table2[[#This Row],[Column2]]-Table2[[#This Row],[Price]] -> 0 | P32: =Table2[[#This Row],[Price]]/Table2[[#This Row],[Total Area (Sq.ft)]] -> 4791.7144 | Q32: =Table2[[#This Row],[Price]]/Table2[[#This Row],[Sellable Area (Sq. ft)]] -> 6800
A33: =IF(Table2[[#This Row],[Unit ]]="","","2 Bedroom") -> 2 Bedroom | B33: Available | C33: 1803 | D33: 18th | E33: =IF(Table2[[#This Row],[Unit ]]="","",_xlfn.XLOOKUP(Table2[[#This Row],[Type]],'Muraba Veil Sale Summary'!A:A,'Muraba Veil Sale Summary'!P:P)) -> 2 | F33: =IF(Table2[[#This Row],[Unit ]]="","",_xlfn.XLOOKUP(Table2[[#This Row],[Type]],'Muraba Veil Sale Summary'!$A:$A,'Muraba Veil Sale Summary'!F:F)) -> 2218.7649 | G33: =IF(Table2[[#This Row],[Unit ]]="","",_xlfn.XLOOKUP(Table2[[#This Row],[Type]],'Muraba Veil Sale Summary'!$A:$A,'Muraba Veil Sale Summary'!G:G)) -> 1619.3227 | H33: =IFERROR(F33+G33,0) -> 3838.0875 | I33: ='Launches Residences'!$U$7 -> 0.3 | J33: =IF(Table2[[#This Row],[Unit ]]="","",F33+(G33*Table2[[#This Row],[Terrace Area]])) -> 2704.5617 | K33: =_xlfn.XLOOKUP(Table2[[#This Row],[Unit ]],'Launches Residences'!$F$15:$F$71,'Launches Residences'!$J$15:$J$71) -> 6800 | L33: =IFERROR(J33*K33,0) -> 18391019 | M33: =Table2[[#This Row],[Price/Sq.ft]] -> 6800 | N33: =VLOOKUP(Table2[[#This Row],[Unit ]],'[1]Muraba Unit Wise Details '!$C$4:$L$67,10,FALSE) -> 18391019 | O33: =Table2[[#This Row],[Column2]]-Table2[[#This Row],[Price]] -> 0 | P33: =Table2[[#This Row],[Price]]/Table2[[#This Row],[Total Area (Sq.ft)]] -> 4791.7144 | Q33: =Table2[[#This Row],[Price]]/Table2[[#This Row],[Sellable Area (Sq. ft)]] -> 6800
A34: =IF(Table2[[#This Row],[Unit ]]="","","2 Bedroom") -> 2 Bedroom | B34: Bank Locked | C34: 1902 | D34: 19th | E34: =IF(Table2[[#This Row],[Unit ]]="","",_xlfn.XLOOKUP(Table2[[#This Row],[Type]],'Muraba Veil Sale Summary'!A:A,'Muraba Veil Sale Summary'!P:P)) -> 2 | F34: =IF(Table2[[#This Row],[Unit ]]="","",_xlfn.XLOOKUP(Table2[[#This Row],[Type]],'Muraba Veil Sale Summary'!$A:$A,'Muraba Veil Sale Summary'!F:F)) -> 2218.7649 | G34: =IF(Table2[[#This Row],[Unit ]]="","",_xlfn.XLOOKUP(Table2[[#This Row],[Type]],'Muraba Veil Sale Summary'!$A:$A,'Muraba Veil Sale Summary'!G:G)) -> 1619.3227 | H34: =IFERROR(F34+G34,0) -> 3838.0875 | I34: ='Launches Residences'!$U$7 -> 0.3 | J34: =IF(Table2[[#This Row],[Unit ]]="","",F34+(G34*Table2[[#This Row],[Terrace Area]])) -> 2704.5617 | K34: =_xlfn.XLOOKUP(Table2[[#This Row],[Unit ]],'Launches Residences'!$E$15:$E$71,'Launches Residences'!$I$15:$I$71) -> 6950 | L34: =IFERROR(J34*K34,0) -> 18796704 | M34: =Table2[[#This Row],[Price/Sq.ft]] -> 6950 | N34: =VLOOKUP(Table2[[#This Row],[Unit ]],'[1]Muraba Unit Wise Details '!$C$4:$L$67,10,FALSE) -> 18796704 | O34: =Table2[[#This Row],[Column2]]-Table2[[#This Row],[Price]] -> 0 | P34: =Table2[[#This Row],[Price]]/Table2[[#This Row],[Total Area (Sq.ft)]] -> 4897.414 | Q34: =Table2[[#This Row],[Price]]/Table2[[#This Row],[Sellable Area (Sq. ft)]] -> 6950
A35: =IF(Table2[[#This Row],[Unit ]]="","","2 Bedroom") -> 2 Bedroom | B35: Bank Locked | C35: 1903 | D35: 19th | E35: =IF(Table2[[#This Row],[Unit ]]="","",_xlfn.XLOOKUP(Table2[[#This Row],[Type]],'Muraba Veil Sale Summary'!A:A,'Muraba Veil Sale Summary'!P:P)) -> 2 | F35: =IF(Table2[[#This Row],[Unit ]]="","",_xlfn.XLOOKUP(Table2[[#This Row],[Type]],'Muraba Veil Sale Summary'!$A:$A,'Muraba Veil Sale Summary'!F:F)) -> 2218.7649 | G35: =IF(Table2[[#This Row],[Unit ]]="","",_xlfn.XLOOKUP(Table2[[#This Row],[Type]],'Muraba Veil Sale Summary'!$A:$A,'Muraba Veil Sale Summary'!G:G)) -> 1619.3227 | H35: =IFERROR(F35+G35,0) -> 3838.0875 | I35: ='Launches Residences'!$U$7 -> 0.3 | J35: =IF(Table2[[#This Row],[Unit ]]="","",F35+(G35*Table2[[#This Row],[Terrace Area]])) -> 2704.5617 | K35: =_xlfn.XLOOKUP(Table2[[#This Row],[Unit ]],'Launches Residences'!$F$15:$F$71,'Launches Residences'!$J$15:$J$71) -> 6950 | L35: =IFERROR(J35*K35,0) -> 18796704 | M35: =Table2[[#This Row],[Price/Sq.ft]] -> 6950 | N35: =VLOOKUP(Table2[[#This Row],[Unit ]],'[1]Muraba Unit Wise Details '!$C$4:$L$67,10,FALSE) -> 18796704 | O35: =Table2[[#This Row],[Column2]]-Table2[[#This Row],[Price]] -> 0 | P35: =Table2[[#This Row],[Price]]/Table2[[#This Row],[Total Area (Sq.ft)]] -> 4897.414 | Q35: =Table2[[#This Row],[Price]]/Table2[[#This Row],[Sellable Area (Sq. ft)]] -> 6950
A36: =IF(Table2[[#This Row],[Unit ]]="","","2 Bedroom") -> 2 Bedroom | B36: Sold | C36: 2002 | D36: 20th | E36: =IF(Table2[[#This Row],[Unit ]]="","",_xlfn.XLOOKUP(Table2[[#This Row],[Type]],'Muraba Veil Sale Summary'!A:A,'Muraba Veil Sale Summary'!P:P)) -> 2 | F36: =IF(Table2[[#This Row],[Unit ]]="","",_xlfn.XLOOKUP(Table2[[#This Row],[Type]],'Muraba Veil Sale Summary'!$A:$A,'Muraba Veil Sale Summary'!F:F)) -> 2218.7649 | G36: =IF(Table2[[#This Row],[Unit ]]="","",_xlfn.XLOOKUP(Table2[[#This Row],[Type]],'Muraba Veil Sale Summary'!$A:$A,'Muraba Veil Sale Summary'!G:G)) -> 1619.3227 | H36: =IFERROR(F36+G36,0) -> 3838.0875 | I36: ='Launches Residences'!$U$7 -> 0.3 | J36: =IF(Table2[[#This Row],[Unit ]]="","",F36+(G36*Table2[[#This Row],[Terrace Area]])) -> 2704.5617 | K36: =_xlfn.XLOOKUP(Table2[[#This Row],[Unit ]],'Launches Residences'!$E$15:$E$71,'Launches Residences'!$I$15:$I$71) -> 5361.3124 | L36: 14500000 | M36: =Table2[[#This Row],[Price/Sq.ft]] -> 5361.3124 | N36: =VLOOKUP(Table2[[#This Row],[Unit ]],'[1]Muraba Unit Wise Details '!$C$4:$L$67,10,FALSE) -> 14500000 | O36: =Table2[[#This Row],[Column2]]-Table2[[#This Row],[Price]] -> 0 | P36: =Table2[[#This Row],[Price]]/Table2[[#This Row],[Total Area (Sq.ft)]] -> 3777.9232 | Q36: =Table2[[#This Row],[Price]]/Table2[[#This Row],[Sellable Area (Sq. ft)]] -> 5361.3124
A37: =IF(Table2[[#This Row],[Unit ]]="","","2 Bedroom") -> 2 Bedroom | B37: Sold | C37: 2003 | D37: 20th | E37: =IF(Table2[[#This Row],[Unit ]]="","",_xlfn.XLOOKUP(Table2[[#This Row],[Type]],'Muraba Veil Sale Summary'!A:A,'Muraba Veil Sale Summary'!P:P)) -> 2 | F37: =IF(Table2[[#This Row],[Unit ]]="","",_xlfn.XLOOKUP(Table2[[#This Row],[Type]],'Muraba Veil Sale Summary'!$A:$A,'Muraba Veil Sale Summary'!F:F)) -> 2218.7649 | G37: =IF(Table2[[#This Row],[Unit ]]="","",_xlfn.XLOOKUP(Table2[[#This Row],[Type]],'Muraba Veil Sale Summary'!$A:$A,'Muraba Veil Sale Summary'!G:G)) -> 1619.3227 | H37: =IFERROR(F37+G37,0) -> 3838.0875 | I37: ='Launches Residences'!$U$7 -> 0.3 | J37: =IF(Table2[[#This Row],[Unit ]]="","",F37+(G37*Table2[[#This Row],[Terrace Area]])) -> 2704.5617 | K37: =_xlfn.XLOOKUP(Table2[[#This Row],[Unit ]],'Launches Residences'!$F$15:$F$71,'Launches Residences'!$J$15:$J$71) -> 5950.0001 | L37: 16092142 | M37: =Table2[[#This Row],[Price/Sq.ft]] -> 5950.0001 | N37: =VLOOKUP(Table2[[#This Row],[Unit ]],'[1]Muraba Unit Wise Details '!$C$4:$L$67,10,FALSE) -> 16092142 | O37: =Table2[[#This Row],[Column2]]-Table2[[#This Row],[Price]] -> 0 | P37: =Table2[[#This Row],[Price]]/Table2[[#This Row],[Total Area (Sq.ft)]] -> 4192.7501 | Q37: =Table2[[#This Row],[Price]]/Table2[[#This Row],[Sellable Area (Sq. ft)]] -> 5950.0001
A38: =IF(Table2[[#This Row],[Unit ]]="","","2 Bedroom") -> 2 Bedroom | B38: Sold | C38: 2102 | D38: 21st | E38: =IF(Table2[[#This Row],[Unit ]]="","",_xlfn.XLOOKUP(Table2[[#This Row],[Type]],'Muraba Veil Sale Summary'!A:A,'Muraba Veil Sale Summary'!P:P)) -> 2 | F38: =IF(Table2[[#This Row],[Unit ]]="","",_xlfn.XLOOKUP(Table2[[#This Row],[Type]],'Muraba Veil Sale Summary'!$A:$A,'Muraba Veil Sale Summary'!F:F)) -> 2218.7649 | G38: =IF(Table2[[#This Row],[Unit ]]="","",_xlfn.XLOOKUP(Table2[[#This Row],[Type]],'Muraba Veil Sale Summary'!$A:$A,'Muraba Veil Sale Summary'!G:G)) -> 1619.3227 | H38: =IFERROR(F38+G38,0) -> 3838.0875 | I38: ='Launches Residences'!$U$7 -> 0.3 | J38: =IF(Table2[[#This Row],[Unit ]]="","",F38+(G38*Table2[[#This Row],[Terrace Area]])) -> 2704.5617 | K38: =_xlfn.XLOOKUP(Table2[[#This Row],[Unit ]],'Launches Residences'!$E$15:$E$71,'Launches Residences'!$I$15:$I$71) -> 6149.9999 | L38: 16633054 | M38: =Table2[[#This Row],[Price/Sq.ft]] -> 6149.9999 | N38: =VLOOKUP(Table2[[#This Row],[Unit ]],'[1]Muraba Unit Wise Details '!$C$4:$L$67,10,FALSE) -> 16633054 | O38: =Table2[[#This Row],[Column2]]-Table2[[#This Row],[Price]] -> 0 | P38: =Table2[[#This Row],[Price]]/Table2[[#This Row],[Total Area (Sq.ft)]] -> 4333.6828 | Q38: =Table2[[#This Row],[Price]]/Table2[[#This Row],[Sellable Area (Sq. ft)]] -> 6149.9999
A39: =IF(Table2[[#This Row],[Unit ]]="","","2 Bedroom") -> 2 Bedroom | B39: Available | C39: 2103 | D39: 21st | E39: =IF(Table2[[#This Row],[Unit ]]="","",_xlfn.XLOOKUP(Table2[[#This Row],[Type]],'Muraba Veil Sale Summary'!A:A,'Muraba Veil Sale Summary'!P:P)) -> 2 | F39: =IF(Table2[[#This Row],[Unit ]]="","",_xlfn.XLOOKUP(Table2[[#This Row],[Type]],'Muraba Veil Sale Summary'!$A:$A,'Muraba Veil Sale Summary'!F:F)) -> 2218.7649 | G39: =IF(Table2[[#This Row],[Unit ]]="","",_xlfn.XLOOKUP(Table2[[#This Row],[Type]],'Muraba Veil Sale Summary'!$A:$A,'Muraba Veil Sale Summary'!G:G)) -> 1619.3227 | H39: =IFERROR(F39+G39,0) -> 3838.0875 | I39: ='Launches Residences'!$U$7 -> 0.3 | J39: =IF(Table2[[#This Row],[Unit ]]="","",F39+(G39*Table2[[#This Row],[Terrace Area]])) -> 2704.5617 | K39: =_xlfn.XLOOKUP(Table2[[#This Row],[Unit ]],'Launches Residences'!$F$15:$F$71,'Launches Residences'!$J$15:$J$71) -> 7100 | L39: =IFERROR(J39*K39,0) -> 19202388 | M39: =Table2[[#This Row],[Price/Sq.ft]] -> 7100 | N39: =VLOOKUP(Table2[[#This Row],[Unit ]],'[1]Muraba Unit Wise Details '!$C$4:$L$67,10,FALSE) -> 19608072 | O39: =Table2[[#This Row],[Column2]]-Table2[[#This Row],[Price]] -> 405684.25 | P39: =Table2[[#This Row],[Price]]/Table2[[#This Row],[Total Area (Sq.ft)]] -> 5003.1136 | Q39: =Table2[[#This Row],[Price]]/Table2[[#This Row],[Sellable Area (Sq. ft)]] -> 7100
A40: =IF(Table2[[#This Row],[Unit ]]="","","2 Bedroom") -> 2 Bedroom | B40: Available | C40: 2202 | D40: 22nd | E40: =IF(Table2[[#This Row],[Unit ]]="","",_xlfn.XLOOKUP(Table2[[#This Row],[Type]],'Muraba Veil Sale Summary'!A:A,'Muraba Veil Sale Summary'!P:P)) -> 2 | F40: =IF(Table2[[#This Row],[Unit ]]="","",_xlfn.XLOOKUP(Table2[[#This Row],[Type]],'Muraba Veil Sale Summary'!$A:$A,'Muraba Veil Sale Summary'!F:F)) -> 2218.7649 | G40: =IF(Table2[[#This Row],[Unit ]]="","",_xlfn.XLOOKUP(Table2[[#This Row],[Type]],'Muraba Veil Sale Summary'!$A:$A,'Muraba Veil Sale Summary'!G:G)) -> 1619.3227 | H40: =IFERROR(F40+G40,0) -> 3838.0875 | I40: ='Launches Residences'!$U$7 -> 0.3 | J40: =IF(Table2[[#This Row],[Unit ]]="","",F40+(G40*Table2[[#This Row],[Terrace Area]])) -> 2704.5617 | K40: =_xlfn.XLOOKUP(Table2[[#This Row],[Unit ]],'Launches Residences'!$E$15:$E$71,'Launches Residences'!$I$15:$I$71) -> 7400 | L40: =IFERROR(J40*K40,0) -> 20013756 | M40: =Table2[[#This Row],[Price/Sq.ft]] -> 7400 | N40: =VLOOKUP(Table2[[#This Row],[Unit ]],'[1]Muraba Unit Wise Details '!$C$4:$L$67,10,FALSE) -> 20013756 | O40: =Table2[[#This Row],[Column2]]-Table2[[#This Row],[Price]] -> 0 | P40: =Table2[[#This Row],[Price]]/Table2[[#This Row],[Total Area (Sq.ft)]] -> 5214.5127 | Q40: =Table2[[#This Row],[Price]]/Table2[[#This Row],[Sellable Area (Sq. ft)]] -> 7400
A41: =IF(Table2[[#This Row],[Unit ]]="","","2 Bedroom") -> 2 Bedroom | B41: Available | C41: 2203 | D41: 22nd | E41: =IF(Table2[[#This Row],[Unit ]]="","",_xlfn.XLOOKUP(Table2[[#This Row],[Type]],'Muraba Veil Sale Summary'!A:A,'Muraba Veil Sale Summary'!P:P)) -> 2 | F41: =IF(Table2[[#This Row],[Unit ]]="","",_xlfn.XLOOKUP(Table2[[#This Row],[Type]],'Muraba Veil Sale Summary'!$A:$A,'Muraba Veil Sale Summary'!F:F)) -> 2218.7649 | G41: =IF(Table2[[#This Row],[Unit ]]="","",_xlfn.XLOOKUP(Table2[[#This Row],[Type]],'Muraba Veil Sale Summary'!$A:$A,'Muraba Veil Sale Summary'!G:G)) -> 1619.3227 | H41: =IFERROR(F41+G41,0) -> 3838.0875 | I41: ='Launches Residences'!$U$7 -> 0.3 | J41: =IF(Table2[[#This Row],[Unit ]]="","",F41+(G41*Table2[[#This Row],[Terrace Area]])) -> 2704.5617 | K41: =_xlfn.XLOOKUP(Table2[[#This Row],[Unit ]],'Launches Residences'!$F$15:$F$71,'Launches Residences'!$J$15:$J$71) -> 7400 | L41: =IFERROR(J41*K41,0) -> 20013756 | M41: =Table2[[#This Row],[Price/Sq.ft]] -> 7400 | N41: =VLOOKUP(Table2[[#This Row],[Unit ]],'[1]Muraba Unit Wise Details '!$C$4:$L$67,10,FALSE) -> 20013756 | O41: =Table2[[#This Row],[Column2]]-Table2[[#This Row],[Price]] -> 0 | P41: =Table2[[#This Row],[Price]]/Table2[[#This Row],[Total Area (Sq.ft)]] -> 5214.5127 | Q41: =Table2[[#This Row],[Price]]/Table2[[#This Row],[Sellable Area (Sq. ft)]] -> 7400
...

Sheet Building  Usman
D2: MURABA VEIL - PRICING | J2: MURABA VEIL - PRICING
C4: LEVELS | D4: UNITS | I4: LEVELS | J4: UNITS
C5: 73 | D5: ROOF POOL, RESTAURANT | I5: 73 | J5: ROOF POOL, RESTAURANT
C6: 72 | I6: 72
C7: 71 | I7: 71
C8: 70 | I8: 70
C9: 69 | D9: 6901- 5BD PH | I9: 69 | J9: 6901- 5BD PH
C10: 68 | I10: 68
C11: 67 | D11: MEP-6 | I11: 67 | J11: MEP-6
